Traceback (most recent call last):
  File "/opt/hostedtoolcache/Python/3.9.19/x64/lib/python3.9/site-packages/jupyter_cache/executors/utils.py", line 58, in single_nb_execution
    executenb(
  File "/opt/hostedtoolcache/Python/3.9.19/x64/lib/python3.9/site-packages/nbclient/client.py", line 1305, in execute
    return NotebookClient(nb=nb, resources=resources, km=km, **kwargs).execute()
  File "/opt/hostedtoolcache/Python/3.9.19/x64/lib/python3.9/site-packages/jupyter_core/utils/__init__.py", line 165, in wrapped
    return loop.run_until_complete(inner)
  File "/opt/hostedtoolcache/Python/3.9.19/x64/lib/python3.9/asyncio/base_events.py", line 647, in run_until_complete
    return future.result()
  File "/opt/hostedtoolcache/Python/3.9.19/x64/lib/python3.9/site-packages/nbclient/client.py", line 705, in async_execute
    await self.async_execute_cell(
  File "/opt/hostedtoolcache/Python/3.9.19/x64/lib/python3.9/site-packages/nbclient/client.py", line 1058, in async_execute_cell
    await self._check_raise_for_error(cell, cell_index, exec_reply)
  File "/opt/hostedtoolcache/Python/3.9.19/x64/lib/python3.9/site-packages/nbclient/client.py", line 914, in _check_raise_for_error
    raise CellExecutionError.from_cell_and_msg(cell, exec_reply_content)
nbclient.exceptions.CellExecutionError: An error occurred while executing the following cell:
------------------
from policyengine_us import Microsimulation

sim = Microsimulation(dataset_year=2020)

sim.calc("md_eitc", period=2022).sum() / 1e6
------------------


[0;31m---------------------------------------------------------------------------[0m
[0;31mTypeError[0m                                 Traceback (most recent call last)
[0;32m/tmp/ipykernel_3136/3217126450.py[0m in [0;36m<cell line: 3>[0;34m()[0m
[1;32m      1[0m [0;32mfrom[0m [0mpolicyengine_us[0m [0;32mimport[0m [0mMicrosimulation[0m[0;34m[0m[0;34m[0m[0m
[1;32m      2[0m [0;34m[0m[0m
[0;32m----> 3[0;31m [0msim[0m [0;34m=[0m [0mMicrosimulation[0m[0;34m([0m[0mdataset_year[0m[0;34m=[0m[0;36m2020[0m[0;34m)[0m[0;34m[0m[0;34m[0m[0m
[0m[1;32m      4[0m [0;34m[0m[0m
[1;32m      5[0m [0msim[0m[0;34m.[0m[0mcalc[0m[0;34m([0m[0;34m"md_eitc"[0m[0;34m,[0m [0mperiod[0m[0;34m=[0m[0;36m2022[0m[0;34m)[0m[0;34m.[0m[0msum[0m[0;34m([0m[0;34m)[0m [0;34m/[0m [0;36m1e6[0m[0;34m[0m[0;34m[0m[0m

[0;32m~/work/policyengine-us/policyengine-us/policyengine_us/system.py[0m in [0;36m__init__[0;34m(self, *args, **kwargs)[0m
[1;32m    117[0m [0;34m[0m[0m
[1;32m    118[0m     [0;32mdef[0m [0m__init__[0m[0;34m([0m[0mself[0m[0;34m,[0m [0;34m*[0m[0margs[0m[0;34m,[0m [0;34m**[0m[0mkwargs[0m[0;34m)[0m[0;34m:[0m[0;34m[0m[0;34m[0m[0m
[0;32m--> 119[0;31m         [0msuper[0m[0;34m([0m[0;34m)[0m[0;34m.[0m[0m__init__[0m[0;34m([0m[0;34m*[0m[0margs[0m[0;34m,[0m [0;34m**[0m[0mkwargs[0m[0;34m)[0m[0;34m[0m[0;34m[0m[0m
[0m[1;32m    120[0m [0;34m[0m[0m
[1;32m    121[0m         reform = create_structural_reforms_from_parameters(

[0;31mTypeError[0m: __init__() got an unexpected keyword argument 'dataset_year'

