Traceback (most recent call last):
  File "/opt/hostedtoolcache/Python/3.9.16/x64/lib/python3.9/site-packages/jupyter_cache/executors/utils.py", line 58, in single_nb_execution
    executenb(
  File "/opt/hostedtoolcache/Python/3.9.16/x64/lib/python3.9/site-packages/nbclient/client.py", line 1304, in execute
    return NotebookClient(nb=nb, resources=resources, km=km, **kwargs).execute()
  File "/opt/hostedtoolcache/Python/3.9.16/x64/lib/python3.9/site-packages/jupyter_core/utils/__init__.py", line 166, in wrapped
    return loop.run_until_complete(inner)
  File "/opt/hostedtoolcache/Python/3.9.16/x64/lib/python3.9/asyncio/base_events.py", line 647, in run_until_complete
    return future.result()
  File "/opt/hostedtoolcache/Python/3.9.16/x64/lib/python3.9/site-packages/nbclient/client.py", line 705, in async_execute
    await self.async_execute_cell(
  File "/opt/hostedtoolcache/Python/3.9.16/x64/lib/python3.9/site-packages/nbclient/client.py", line 1020, in async_execute_cell
    await self._check_raise_for_error(cell, cell_index, exec_reply)
  File "/opt/hostedtoolcache/Python/3.9.16/x64/lib/python3.9/site-packages/nbclient/client.py", line 914, in _check_raise_for_error
    raise CellExecutionError.from_cell_and_msg(cell, exec_reply_content)
nbclient.exceptions.CellExecutionError: An error occurred while executing the following cell:
------------------
variation_chart(
    "lifeline",
    additional_data=dict(
        spm_units=dict(
            spm_unit=dict(
                broadband_cost=40 * 12,
            )
        )
    ),
)
------------------

[0;31m---------------------------------------------------------------------------[0m
[0;31mTypeError[0m                                 Traceback (most recent call last)
Cell [0;32mIn[2], line 1[0m
[0;32m----> 1[0m [43mvariation_chart[49m[43m([49m
[1;32m      2[0m [43m    [49m[38;5;124;43m"[39;49m[38;5;124;43mlifeline[39;49m[38;5;124;43m"[39;49m[43m,[49m
[1;32m      3[0m [43m    [49m[43madditional_data[49m[38;5;241;43m=[39;49m[38;5;28;43mdict[39;49m[43m([49m
[1;32m      4[0m [43m        [49m[43mspm_units[49m[38;5;241;43m=[39;49m[38;5;28;43mdict[39;49m[43m([49m
[1;32m      5[0m [43m            [49m[43mspm_unit[49m[38;5;241;43m=[39;49m[38;5;28;43mdict[39;49m[43m([49m
[1;32m      6[0m [43m                [49m[43mbroadband_cost[49m[38;5;241;43m=[39;49m[38;5;241;43m40[39;49m[43m [49m[38;5;241;43m*[39;49m[43m [49m[38;5;241;43m12[39;49m[43m,[49m
[1;32m      7[0m [43m            [49m[43m)[49m
[1;32m      8[0m [43m        [49m[43m)[49m
[1;32m      9[0m [43m    [49m[43m)[49m[43m,[49m
[1;32m     10[0m [43m)[49m

[0;31mTypeError[0m: variation_chart() got an unexpected keyword argument 'additional_data'
TypeError: variation_chart() got an unexpected keyword argument 'additional_data'

